<?xml version="1.0" ?>
<sdf version="1.8">
    <!-- Define the world environment -->
    <world name="rover_world">
        <!-- Define the world's gravity -->
        <gravity>0 0 -9.81</gravity>
        
        <!-- Physics settings for the simulation -->
        <physics name="1ms" type="ignored">
            <max_step_size>0.001</max_step_size> <!-- Simulation step size -->
            <real_time_factor>1.0</real_time_factor> <!-- Speed relative to real-time -->
        </physics>
        
        <!-- Plugins to extend Gazebo functionalities -->
        <!-- Default physics engine -->
        <plugin
            filename="libignition-gazebo-physics-system.so" 
            name="ignition::gazebo::systems::Physics">
        </plugin>
        <!-- User commands for controlling the simulation -->
        <plugin 
            filename="libignition-gazebo-user-commands-system.so" 
            name="ignition::gazebo::systems::UserCommands">
        </plugin>        
        <!-- Broadcasts the scene to GUI clients -->
        <plugin 
            filename="libignition-gazebo-scene-broadcaster-system.so" 
            name="ignition::gazebo::systems::SceneBroadcaster">
        </plugin>
        
        <!-- Define a directional light (e.g., sun) -->
        <light type="directional" name="sun">
            <!-- Enable shadow casting -->
            <cast_shadows>true</cast_shadows> 
            <!-- Position in the world -->
            <!-- <pose> x y z roll pitch yaw </pose> -->
            <pose>0 0 10 0 0 0</pose> 
            <!-- Light direction (mostly downward) -->
            <direction>-0.5 0.1 -0.9</direction>
            <!-- Diffuse (i.e., scattered) light -->
            <!-- <diffuse> R G B alpha </diffuse> -->
            <!-- Fully opaque light gray -->
            <diffuse>0.8 0.8 0.8 1</diffuse> 
            <!-- Shiny highlights on reflective surfaces -->
            <!-- Fully opaque dark gray -->
            <specular>0.2 0.2 0.2 1</specular>
            <!-- Attenuation over distance -->
            <attenuation>
                <!-- Max distance light travels -->
                <range>1000</range>
                <!-- Quadratic fun of distance -->
                <!-- Light = 1 / (C + L * d + Q * d^2) -->
                <constant>0.9</constant>    <!-- C -->
                <linear>0.01</linear>       <!-- L -->
                <quadratic>0.001</quadratic> <!-- Q -->
            </attenuation>
        </light>
        
        <!-- Define a ground plane -->
        <model name="ground_plane">
            <static>true</static> <!-- The ground does not move -->
            <link name="link">
                <collision name="collision">
                    <geometry>
                        <plane>
                            <!-- Flat horizontal surface -->
                            <normal>0 0 1</normal> 
                        </plane>
                    </geometry>
                </collision>
                <visual name="visual">
                    <geometry>
                        <plane>
                            <!-- Flat horizontal surface -->
                            <normal>0 0 1</normal>
                            <!-- Ground size -->
                            <size>100 100</size> 
                        </plane>
                    </geometry>
                    <material> <!-- Ground color -->
                        <ambient>0.8 0.8 0.8 1</ambient> <!-- Base color -->
                        <diffuse>0.8 0.8 0.8 1</diffuse>
                        <specular>0.8 0.8 0.8 1</specular>
                    </material>
                </visual>
            </link>
        </model>
        
        <!-- Define a simple rover model -->
        <model name='rover_blue' canonical_link='chassis'>
            <!-- Position of the rover in the world -->
            <pose relative_to='world'>0 0 0 0 0 0</pose>
            
            <!-- Chassis (main body) of the rover -->
            <link name='chassis'>
                <pose relative_to='__model__'>0.5 0 0.4 0 0 0</pose>
                
                <!-- Inertial properties for physics simulation -->
                <inertial>
                    <mass>1.14395</mass>
                    <inertia>
                        <ixx>0.095329</ixx>
                        <ixy>0</ixy>
                        <ixz>0</ixz>
                        <iyy>0.381317</iyy>
                        <iyz>0</iyz>
                        <izz>0.476646</izz>
                    </inertia>
                </inertial>
                
                <!-- Visual representation of the chassis -->
                <visual name='visual'>
                    <geometry>
                        <box>
                            <!-- Chassis dimensions -->
                            <size>2.0 1.0 0.5</size> 
                        </box>
                    </geometry>
                    <material> <!-- Color of the chassis (Blue) -->
                        <ambient>0.0 0.0 1.0 1</ambient>
                        <diffuse>0.0 0.0 1.0 1</diffuse>
                        <specular>0.0 0.0 1.0 1</specular>
                    </material>
                </visual>
                
                <!-- Collision properties for physics simulation -->
                <collision name='collision'>
                    <geometry>
                        <box>
                            <!-- Same size as visual -->
                            <size>2.0 1.0 0.5</size> 
                        </box>
                    </geometry>
                </collision>
            </link>

            <!-- The left wheel link: -->
            <link name='left_wheel'>
                <!-- Back (-x) and left (+y) position -->
                <!-- The wheel is a cylinder rotated 90 deg 
                around the Roll axis -->
                <pose relative_to="chassis">
                    -0.5 0.6 0 -1.5707 0 0</pose>
                <inertial>
                    <mass>1</mass>
                    <inertia>
                        <ixx>0.043333</ixx>
                        <ixy>0</ixy>
                        <ixz>0</ixz>
                        <iyy>0.043333</iyy>
                        <iyz>0</iyz>
                        <izz>0.08</izz>
                    </inertia>
                </inertial>
                <visual name='visual'>
                    <geometry>
                        <cylinder>
                            <radius>0.4</radius>
                            <length>0.2</length>
                        </cylinder>
                    </geometry>
                    <material>
                        <!-- Red -->
                        <ambient>1.0 0.0 0.0 1</ambient>
                        <diffuse>1.0 0.0 0.0 1</diffuse>
                        <specular>1.0 0.0 0.0 1</specular>
                    </material>
                </visual>
                <collision name='collision'>
                <!-- Same as visual -->
                    <geometry>
                        <cylinder>
                            <radius>0.4</radius>
                            <length>0.2</length>
                        </cylinder>
                    </geometry>
                </collision>
            </link>

            <!--The right wheel is the same as the left wheel 
            but with different position-->
            <link name='right_wheel'>
                <!-- Back (-x) and right (-y) position -->
                <pose relative_to="chassis"> -0.5 -0.6 0 -1.5707 0 0</pose> 
                <inertial>
                    <mass>1</mass>
                    <inertia>
                        <ixx>0.043333</ixx>
                        <ixy>0</ixy>
                        <ixz>0</ixz>
                        <iyy>0.043333</iyy>
                        <iyz>0</iyz>
                        <izz>0.08</izz>
                    </inertia>
                </inertial>
                <visual name='visual'>
                    <geometry>
                        <cylinder>
                            <radius>0.4</radius>
                            <length>0.2</length>
                        </cylinder>
                    </geometry>
                    <material>
                        <ambient>1.0 0.0 0.0 1</ambient>
                        <diffuse>1.0 0.0 0.0 1</diffuse>
                        <specular>1.0 0.0 0.0 1</specular>
                    </material>
                </visual>
                <collision name='collision'>
                    <geometry>
                        <cylinder>
                            <radius>0.4</radius>
                            <length>0.2</length>
                        </cylinder>
                    </geometry>
                </collision>
            </link>

            <!-- For convenience, we define a new frame 
            for the caster wheel -->
            <frame name="caster_frame" attached_to='chassis'>
                <!-- Front (+x) and below (-z) -->
                <pose>0.8 0 -0.2 0 0 0</pose> 
            </frame>
            <!--caster wheel-->
            <link name='caster'>
                <pose relative_to='caster_frame'/>
                <inertial>
                    <mass>1</mass>
                    <inertia>
                        <ixx>0.016</ixx>
                        <ixy>0</ixy>
                        <ixz>0</ixz>
                        <iyy>0.016</iyy>
                        <iyz>0</iyz>
                        <izz>0.016</izz>
                    </inertia>
                </inertial>
                <visual name='visual'>
                    <geometry>
                        <!-- Note: the caster wheel is a sphere, 
                        not a cylinder -->
                        <sphere>
                            <radius>0.2</radius>
                        </sphere>
                    </geometry>
                    <material>
                        <ambient>0.0 1 0.0 1</ambient>
                        <diffuse>0.0 1 0.0 1</diffuse>
                        <specular>0.0 1 0.0 1</specular>
                    </material>
                </visual>
                <collision name='collision'>
                    <geometry>
                        <sphere>
                            <radius>0.2</radius>
                        </sphere>
                    </geometry>
                </collision>
            </link>

            <joint name='left_wheel_joint' type='revolute'>
                <pose relative_to='left_wheel'/>
                <parent>chassis</parent>
                <child>left_wheel</child>
                <axis>
                    <!--can be defined as any frame or even 
                    arbitrary frames-->
                    <xyz expressed_in='__model__'>0 1 0</xyz> 
                    <limit>
                        <!--negative infinity-->
                        <lower>-1.79769e+308</lower>    
                        <!--positive infinity-->
                        <upper>1.79769e+308</upper>     
                    </limit>
                </axis>
            </joint>

            <joint name='right_wheel_joint' type='revolute'>
                <pose relative_to='right_wheel'/>
                <parent>chassis</parent>
                <child>right_wheel</child>
                <axis>
                    <xyz expressed_in='__model__'>0 1 0</xyz>
                    <limit>
                        <!--negative infinity-->
                        <lower>-1.79769e+308</lower>    
                        <!--positive infinity-->
                        <upper>1.79769e+308</upper>     
                    </limit>
                </axis>
            </joint>

            <joint name='caster_wheel' type='ball'>
                <parent>chassis</parent>
                <child>caster</child>
            </joint>

            <plugin
                filename="libignition-gazebo-diff-drive-system.so"
                name="ignition::gazebo::systems::DiffDrive">
                <left_joint>left_wheel_joint</left_joint>
                <right_joint>right_wheel_joint</right_joint>
                <wheel_separation>1.2</wheel_separation> <!-- (-0.6 to 0.6) -->
                <wheel_radius>0.4</wheel_radius>       <!-- Cylinder radius -->
                <odom_publish_frequency>1</odom_publish_frequency>
                <topic>cmd_vel</topic>
            </plugin>

        </model>
    </world>
</sdf>
